<?xml version="1.0" encoding="utf-8"?>
<!-- This URDF was automatically created by SolidWorks to URDF Exporter! Originally created by Stephen Brawner (brawner@gmail.com) 
     Commit Version: 1.6.0-4-g7f85cfe  Build Version: 1.6.7995.38578
     For more information, please see http://wiki.ros.org/sw_urdf_exporter -->
<robot
  name="3rps">
  <link
    name="base_link">
    <inertial>
      <origin
        xyz="0.00147501950493725 0.00585026716726001 -0.0246920187151703"
        rpy="0 0 0" />
      <mass
        value="0.343366641532479" />
      <inertia
        ixx="0.000840538952459364"
        ixy="-2.53367030319271E-07"
        ixz="-4.50736665130116E-08"
        iyy="0.00166994924359932"
        iyz="3.66626613954449E-07"
        izz="0.000840483092628045" />
    </inertial>
    <visual>
      <origin
        xyz="0 0 0"
        rpy="0 0 0" />
      <geometry>
        <mesh
          filename="package://3rps/meshes/base_link.STL" />
      </geometry>
      <material
        name="">
        <color
          rgba="0.792156862745098 0.819607843137255 0.933333333333333 1" />
      </material>
    </visual>
    <collision>
      <origin
        xyz="0 0 0"
        rpy="0 0 0" />
      <geometry>
        <mesh
          filename="package://3rps/meshes/base_link.STL" />
      </geometry>
    </collision>
  </link>
  <link
    name="l1">
    <inertial>
      <origin
        xyz="0.0345 6.93889390390723E-18 -0.0299548821668228"
        rpy="0 0 0" />
      <mass
        value="0.0034857920578331" />
      <inertia
        ixx="3.79565695887464E-08"
        ixy="1.29867356170825E-22"
        ixz="-3.69749733811203E-22"
        iyy="1.45004556642459E-06"
        iyz="-2.64697796016969E-23"
        izz="1.47347800243903E-06" />
    </inertial>
    <visual>
      <origin
        xyz="0 0 0"
        rpy="0 0 0" />
      <geometry>
        <mesh
          filename="package://3rps/meshes/l1.STL" />
      </geometry>
      <material
        name="">
        <color
          rgba="0.792156862745098 0.819607843137255 0.933333333333333 1" />
      </material>
    </visual>
    <collision>
      <origin
        xyz="0 0 0"
        rpy="0 0 0" />
      <geometry>
        <mesh
          filename="package://3rps/meshes/l1.STL" />
      </geometry>
    </collision>
  </link>
  <joint
    name="l1"
    type="continuous">
    <origin
      xyz="-0.016725 -0.072844 0.015152"
      rpy="-1.5708 -0.69883 -2.0884" />
    <parent
      link="base_link" />
    <child
      link="l1" />
    <axis
      xyz="0 0 -1" />
  </joint>
  <link
    name="e1">
    <inertial>
      <origin
        xyz="0.0458398693820964 2.59863996027176E-06 -0.018796807276071"
        rpy="0 0 0" />
      <mass
        value="0.00487433629385641" />
      <inertia
        ixx="5.18303688110237E-08"
        ixy="-5.84693991059332E-10"
        ixz="-2.92346995529835E-10"
        iyy="3.91488075562568E-06"
        iyz="6.54844008870915E-13"
        izz="3.94612977335967E-06" />
    </inertial>
    <visual>
      <origin
        xyz="0 0 0"
        rpy="0 0 0" />
      <geometry>
        <mesh
          filename="package://3rps/meshes/e1.STL" />
      </geometry>
      <material
        name="">
        <color
          rgba="0.792156862745098 0.819607843137255 0.933333333333333 1" />
      </material>
    </visual>
    <collision>
      <origin
        xyz="0 0 0"
        rpy="0 0 0" />
      <geometry>
        <mesh
          filename="package://3rps/meshes/e1.STL" />
      </geometry>
    </collision>
  </link>
  <joint
    name="e1"
    type="continuous">
    <origin
      xyz="0.069 0 -0.016157"
      rpy="0 0 -1.159" />
    <parent
      link="l1" />
    <child
      link="e1" />
    <axis
      xyz="0 0 -1" />
  </joint>
  <link
    name="b1">
    <inertial>
      <origin
        xyz="-0.0144458954802205 -2.77555756156289E-17 0"
        rpy="0 0 0" />
      <mass
        value="0.00047243106832359" />
      <inertia
        ixx="2.12666790996715E-09"
        ixy="-4.29099942761883E-24"
        ixz="7.26367975398127E-24"
        iyy="2.27607764209083E-08"
        iyz="1.65436122510606E-24"
        izz="2.27607764209083E-08" />
    </inertial>
    <visual>
      <origin
        xyz="0 0 0"
        rpy="0 0 0" />
      <geometry>
        <mesh
          filename="package://3rps/meshes/b1.STL" />
      </geometry>
      <material
        name="">
        <color
          rgba="0.792156862745098 0.819607843137255 0.933333333333333 1" />
      </material>
    </visual>
    <collision>
      <origin
        xyz="0 0 0"
        rpy="0 0 0" />
      <geometry>
        <mesh
          filename="package://3rps/meshes/b1.STL" />
      </geometry>
    </collision>
  </link>
  <joint
    name="b1"
    type="fixed">
    <origin
      xyz="0.080885 -0.0001008 -0.018849"
      rpy="2.267 0 -3.1416" />
    <parent
      link="e1" />
    <child
      link="b1" />
    <axis
      xyz="0 0 0" />
  </joint>
  <link
    name="s1">
    <inertial>
      <origin
        xyz="0.00682295115101317 -0.00315759519083211 -0.00492142509620176"
        rpy="0 0 0" />
      <mass
        value="0.000125413134072923" />
      <inertia
        ixx="4.82944924242953E-10"
        ixy="7.91514190382975E-26"
        ixz="3.05285199304351E-25"
        iyy="8.16445338204102E-10"
        iyz="0"
        izz="8.16445338204102E-10" />
    </inertial>
    <visual>
      <origin
        xyz="0 0 0"
        rpy="0 0 0" />
      <geometry>
        <mesh
          filename="package://3rps/meshes/s1.STL" />
      </geometry>
      <material
        name="">
        <color
          rgba="0.792156862745098 0.819607843137255 0.933333333333333 1" />
      </material>
    </visual>
    <collision>
      <origin
        xyz="0 0 0"
        rpy="0 0 0" />
      <geometry>
        <mesh
          filename="package://3rps/meshes/s1.STL" />
      </geometry>
    </collision>
  </link>
  <joint
    name="s1"
    type="fixed">
    <origin
      xyz="-0.018141 0.0053451 0.0018842"
      rpy="1.8048 -0.21901 2.9545" />
    <parent
      link="b1" />
    <child
      link="s1" />
    <axis
      xyz="0 0 0" />
  </joint>
  <link
    name="platform">
    <inertial>
      <origin
        xyz="0.246561359482376 0.137644239301135 0.151371743234073"
        rpy="0 0 0" />
      <mass
        value="0.49068535656419" />
      <inertia
        ixx="0.00192021855152557"
        ixy="1.44190225086158E-11"
        ixz="4.57007478735227E-15"
        iyy="0.00383225901450391"
        iyz="3.73520044576916E-13"
        izz="0.00192021855134928" />
    </inertial>
    <visual>
      <origin
        xyz="0 0 0"
        rpy="0 0 0" />
      <geometry>
        <mesh
          filename="package://3rps/meshes/platform.STL" />
      </geometry>
      <material
        name="">
        <color
          rgba="0.792156862745098 0.819607843137255 0.933333333333333 1" />
      </material>
    </visual>
    <collision>
      <origin
        xyz="0 0 0"
        rpy="0 0 0" />
      <geometry>
        <mesh
          filename="package://3rps/meshes/platform.STL" />
      </geometry>
    </collision>
  </link>
  <joint
    name="platform"
    type="fixed">
    <origin
      xyz="-0.12564 0.05024 0.18269"
      rpy="0 1.5334 -1.5708" />
    <parent
      link="s1" />
    <child
      link="platform" />
    <axis
      xyz="0 0 0" />
  </joint>
  <link
    name="s2">
    <inertial>
      <origin
        xyz="0.0068229511510132 -2.77555756156289E-17 4.16333634234434E-17"
        rpy="0 0 0" />
      <mass
        value="0.000125413134072923" />
      <inertia
        ixx="4.82944924242953E-10"
        ixy="1.8807618955357E-25"
        ixz="2.92971523964052E-25"
        iyy="8.16445338204101E-10"
        iyz="-7.75481824268463E-26"
        izz="8.16445338204101E-10" />
    </inertial>
    <visual>
      <origin
        xyz="0 0 0"
        rpy="0 0 0" />
      <geometry>
        <mesh
          filename="package://3rps/meshes/s2.STL" />
      </geometry>
      <material
        name="">
        <color
          rgba="0.792156862745098 0.819607843137255 0.933333333333333 1" />
      </material>
    </visual>
    <collision>
      <origin
        xyz="0 0 0"
        rpy="0 0 0" />
      <geometry>
        <mesh
          filename="package://3rps/meshes/s2.STL" />
      </geometry>
    </collision>
  </link>
  <joint
    name="s2"
    type="fixed">
    <origin
      xyz="0.18411 0.12564 0.25329"
      rpy="-1.5334 0 1.5708" />
    <parent
      link="platform" />
    <child
      link="s2" />
    <axis
      xyz="0 0 0" />
  </joint>
  <link
    name="s3">
    <inertial>
      <origin
        xyz="0.00682295115101317 2.77555756156289E-17 5.55111512312578E-17"
        rpy="0 0 0" />
      <mass
        value="0.000125413134072923" />
      <inertia
        ixx="4.82944924242953E-10"
        ixy="-4.84972692233821E-26"
        ixz="-9.77022299952032E-26"
        iyy="8.164453382041E-10"
        iyz="-2.58493941422821E-26"
        izz="8.164453382041E-10" />
    </inertial>
    <visual>
      <origin
        xyz="0 0 0"
        rpy="0 0 0" />
      <geometry>
        <mesh
          filename="package://3rps/meshes/s3.STL" />
      </geometry>
      <material
        name="">
        <color
          rgba="0.792156862745098 0.819607843137255 0.933333333333333 1" />
      </material>
    </visual>
    <collision>
      <origin
        xyz="0 0 0"
        rpy="0 0 0" />
      <geometry>
        <mesh
          filename="package://3rps/meshes/s3.STL" />
      </geometry>
    </collision>
  </link>
  <joint
    name="s3"
    type="fixed">
    <origin
      xyz="0.36601 0.12564 0.15447"
      rpy="-1.5334 0 1.5708" />
    <parent
      link="platform" />
    <child
      link="s3" />
    <axis
      xyz="0 0 0" />
  </joint>
  <link
    name="l2">
    <inertial>
      <origin
        xyz="0.0345 -6.93889390390723E-18 -0.00288587942099125"
        rpy="0 0 0" />
      <mass
        value="0.0034857920578331" />
      <inertia
        ixx="3.7956569588746E-08"
        ixy="1.73527689696511E-22"
        ixz="2.09897080435331E-22"
        iyy="1.45004556642459E-06"
        iyz="-4.96308367531817E-24"
        izz="1.47347800243904E-06" />
    </inertial>
    <visual>
      <origin
        xyz="0 0 0"
        rpy="0 0 0" />
      <geometry>
        <mesh
          filename="package://3rps/meshes/l2.STL" />
      </geometry>
      <material
        name="">
        <color
          rgba="0.792156862745098 0.819607843137255 0.933333333333333 1" />
      </material>
    </visual>
    <collision>
      <origin
        xyz="0 0 0"
        rpy="0 0 0" />
      <geometry>
        <mesh
          filename="package://3rps/meshes/l2.STL" />
      </geometry>
    </collision>
  </link>
  <joint
    name="l2"
    type="continuous">
    <origin
      xyz="0.096209 0.025933 0.015152"
      rpy="1.5708 -0.69315 0.0060218" />
    <parent
      link="base_link" />
    <child
      link="l2" />
    <axis
      xyz="0 0 -1" />
  </joint>
  <link
    name="e2">
    <inertial>
      <origin
        xyz="0.0458398693820964 2.59863996027176E-06 -0.00211282125902864"
        rpy="0 0 0" />
      <mass
        value="0.00487433629385641" />
      <inertia
        ixx="5.18303688110235E-08"
        ixy="-5.8469399105818E-10"
        ixz="-2.92346995529201E-10"
        iyy="3.91488075562568E-06"
        iyz="6.54844009057857E-13"
        izz="3.94612977335967E-06" />
    </inertial>
    <visual>
      <origin
        xyz="0 0 0"
        rpy="0 0 0" />
      <geometry>
        <mesh
          filename="package://3rps/meshes/e2.STL" />
      </geometry>
      <material
        name="">
        <color
          rgba="0.792156862745098 0.819607843137255 0.933333333333333 1" />
      </material>
    </visual>
    <collision>
      <origin
        xyz="0 0 0"
        rpy="0 0 0" />
      <geometry>
        <mesh
          filename="package://3rps/meshes/e2.STL" />
      </geometry>
    </collision>
  </link>
  <joint
    name="e2"
    type="continuous">
    <origin
      xyz="0.069 0 0"
      rpy="3.1416 0 1.154" />
    <parent
      link="l2" />
    <child
      link="e2" />
    <axis
      xyz="0 0 1" />
  </joint>
  <link
    name="b2">
    <inertial>
      <origin
        xyz="-0.0130825812680573 2.08166817117217E-17 5.55111512312578E-17"
        rpy="0 0 0" />
      <mass
        value="0.000472431068323591" />
      <inertia
        ixx="2.12666790996716E-09"
        ixy="1.18549764401124E-23"
        ixz="-8.01866381648847E-24"
        iyy="2.27607764209084E-08"
        iyz="-4.13590306276514E-25"
        izz="2.27607764209084E-08" />
    </inertial>
    <visual>
      <origin
        xyz="0 0 0"
        rpy="0 0 0" />
      <geometry>
        <mesh
          filename="package://3rps/meshes/b2.STL" />
      </geometry>
      <material
        name="">
        <color
          rgba="0.792156862745098 0.819607843137255 0.933333333333333 1" />
      </material>
    </visual>
    <collision>
      <origin
        xyz="0 0 0"
        rpy="0 0 0" />
      <geometry>
        <mesh
          filename="package://3rps/meshes/b2.STL" />
      </geometry>
    </collision>
  </link>
  <joint
    name="b2"
    type="fixed">
    <origin
      xyz="0.082248 -0.0001008 -0.0021645"
      rpy="1.3638 0 -3.1416" />
    <parent
      link="e2" />
    <child
      link="b2" />
    <axis
      xyz="0 0 0" />
  </joint>
  <link
    name="l3">
    <inertial>
      <origin
        xyz="0.0345 0 0.0012238350004849"
        rpy="0 0 0" />
      <mass
        value="0.0034857920578331" />
      <inertia
        ixx="3.79565695887467E-08"
        ixy="-4.96308367531817E-23"
        ixz="-7.0227634005752E-22"
        iyy="1.45004556642459E-06"
        iyz="1.32348898008484E-22"
        izz="1.47347800243903E-06" />
    </inertial>
    <visual>
      <origin
        xyz="0 0 0"
        rpy="0 0 0" />
      <geometry>
        <mesh
          filename="package://3rps/meshes/l3.STL" />
      </geometry>
      <material
        name="">
        <color
          rgba="0.792156862745098 0.819607843137255 0.933333333333333 1" />
      </material>
    </visual>
    <collision>
      <origin
        xyz="0 0 0"
        rpy="0 0 0" />
      <geometry>
        <mesh
          filename="package://3rps/meshes/l3.STL" />
      </geometry>
    </collision>
  </link>
  <joint
    name="l3"
    type="continuous">
    <origin
      xyz="-0.046953 0.10309 0.015152"
      rpy="1.5708 -0.68303 2.1004" />
    <parent
      link="base_link" />
    <child
      link="l3" />
    <axis
      xyz="0 0 -1" />
  </joint>
  <link
    name="e3">
    <inertial>
      <origin
        xyz="0.0458398693820964 2.59863996024401E-06 0.001225134320465"
        rpy="0 0 0" />
      <mass
        value="0.00487433629385641" />
      <inertia
        ixx="5.18303688110234E-08"
        ixy="-5.84693991058521E-10"
        ixz="-2.92346995527896E-10"
        iyy="3.91488075562568E-06"
        iyz="6.54844009188552E-13"
        izz="3.94612977335966E-06" />
    </inertial>
    <visual>
      <origin
        xyz="0 0 0"
        rpy="0 0 0" />
      <geometry>
        <mesh
          filename="package://3rps/meshes/e3.STL" />
      </geometry>
      <material
        name="">
        <color
          rgba="0.792156862745098 0.819607843137255 0.933333333333333 1" />
      </material>
    </visual>
    <collision>
      <origin
        xyz="0 0 0"
        rpy="0 0 0" />
      <geometry>
        <mesh
          filename="package://3rps/meshes/e3.STL" />
      </geometry>
    </collision>
  </link>
  <joint
    name="e3"
    type="continuous">
    <origin
      xyz="0.069 0 0.005"
      rpy="0 0 1.1458" />
    <parent
      link="l3" />
    <child
      link="e3" />
    <axis
      xyz="0 0 -1" />
  </joint>
  <link
    name="b3">
    <inertial>
      <origin
        xyz="-0.0180851488386009 -2.77555756156289E-17 2.77555756156289E-17"
        rpy="0 0 0" />
      <mass
        value="0.00047243106832359" />
      <inertia
        ixx="2.12666790996715E-09"
        ixy="2.86928274979331E-23"
        ixz="-9.12483613222559E-24"
        iyy="2.27607764209083E-08"
        iyz="-8.27180612553028E-25"
        izz="2.27607764209083E-08" />
    </inertial>
    <visual>
      <origin
        xyz="0 0 0"
        rpy="0 0 0" />
      <geometry>
        <mesh
          filename="package://3rps/meshes/b3.STL" />
      </geometry>
      <material
        name="">
        <color
          rgba="0.792156862745098 0.819607843137255 0.933333333333333 1" />
      </material>
    </visual>
    <collision>
      <origin
        xyz="0 0 0"
        rpy="0 0 0" />
      <geometry>
        <mesh
          filename="package://3rps/meshes/b3.STL" />
      </geometry>
    </collision>
  </link>
  <joint
    name="b3"
    type="fixed">
    <origin
      xyz="0.077245 -0.0001008 0.0011734"
      rpy="1.0995 0 -3.1416" />
    <parent
      link="e3" />
    <child
      link="b3" />
    <axis
      xyz="0 0 0" />
  </joint>
</robot>